Workbook

Sheet RawData
A1: captured_at | B1: group_name | C1: sender | D1: message_id | E1: raw_text | F1: customer | G1: product | H1: amount | I1: phone | J1: parse_status | K1: order_month | L1: customer_key | M1: first_customer_flag
A2: 45933.417 | B2: Dubai Retail Sales | C2: Rahul | D2: wamid-0001 | E2: Sale: customer=Sara James, product=MacBook Air, amount=84999, phone=9339670711 | F2: Sara James | G2: MacBook Air | H2: 84999 | I2: 9339670711 | J2: parsed | K2: =IF(A2="","",DATE(YEAR(A2),MONTH(A2),1)) | L2: =IF(F2<>"",LOWER(TRIM(F2)),D2) | M2: =IF(L2="","",IF(COUNTIF($L$2:L2,L2)=1,1,0))
A3: 45935.417 | B3: Dubai Retail Sales | C3: Priya | D3: wamid-0002 | E3: Sale: customer=Yusuf Ahmed, product=MacBook Air, amount=82499, phone=9193349856 | F3: Yusuf Ahmed | G3: MacBook Air | H3: 82499 | I3: 9193349856 | J3: parsed | K3: =IF(A3="","",DATE(YEAR(A3),MONTH(A3),1)) | L3: =IF(F3<>"",LOWER(TRIM(F3)),D3) | M3: =IF(L3="","",IF(COUNTIF($L$2:L3,L3)=1,1,0))
A4: 45937.417 | B4: Dubai Retail Sales | C4: Priya | D4: wamid-0003 | E4: Sale: customer=Sara James, product=Apple Watch, amount=22999, phone=9642621108 | F4: Sara James | G4: Apple Watch | H4: 22999 | I4: 9642621108 | J4: parsed | K4: =IF(A4="","",DATE(YEAR(A4),MONTH(A4),1)) | L4: =IF(F4<>"",LOWER(TRIM(F4)),D4) | M4: =IF(L4="","",IF(COUNTIF($L$2:L4,L4)=1,1,0))
A5: 45939.417 | B5: Dubai Retail Sales | C5: Rahul | D5: wamid-0004 | E5: Sale: customer=Yusuf Ahmed, product=iPhone 15, amount=47499, phone=9550455977 | F5: Yusuf Ahmed | G5: iPhone 15 | H5: 47499 | I5: 9550455977 | J5: parsed | K5: =IF(A5="","",DATE(YEAR(A5),MONTH(A5),1)) | L5: =IF(F5<>"",LOWER(TRIM(F5)),D5) | M5: =IF(L5="","",IF(COUNTIF($L$2:L5,L5)=1,1,0))
A6: 45940.417 | B6: Dubai Retail Sales | C6: Noah | D6: wamid-0005 | E6: Sale: customer=Ali Khan, product=Apple Watch, amount=22999, phone=9849621470 | F6: Ali Khan | G6: Apple Watch | H6: 22999 | I6: 9849621470 | J6: parsed | K6: =IF(A6="","",DATE(YEAR(A6),MONTH(A6),1)) | L6: =IF(F6<>"",LOWER(TRIM(F6)),D6) | M6: =IF(L6="","",IF(COUNTIF($L$2:L6,L6)=1,1,0))
A7: 45942.417 | B7: Dubai Retail Sales | C7: Aisha | D7: wamid-0006 | E7: Sale: customer=Nora Salem, product=AirPods Pro, amount=18999, phone=9209747451 | F7: Nora Salem | G7: AirPods Pro | H7: 18999 | I7: 9209747451 | J7: parsed | K7: =IF(A7="","",DATE(YEAR(A7),MONTH(A7),1)) | L7: =IF(F7<>"",LOWER(TRIM(F7)),D7) | M7: =IF(L7="","",IF(COUNTIF($L$2:L7,L7)=1,1,0))
A8: 45945.417 | B8: Dubai Retail Sales | C8: Aisha | D8: wamid-0007 | E8: Sale: customer=Anya Verma, product=Apple Watch, amount=22999, phone=9384027113 | F8: Anya Verma | G8: Apple Watch | H8: 22999 | I8: 9384027113 | J8: parsed | K8: =IF(A8="","",DATE(YEAR(A8),MONTH(A8),1)) | L8: =IF(F8<>"",LOWER(TRIM(F8)),D8) | M8: =IF(L8="","",IF(COUNTIF($L$2:L8,L8)=1,1,0))
A9: 45946.417 | B9: Dubai Retail Sales | C9: Priya | D9: wamid-0008 | E9: Sale: customer=Kabir Singh, product=MacBook Air, amount=83199, phone=9184611066 | F9: Kabir Singh | G9: MacBook Air | H9: 83199 | I9: 9184611066 | J9: parsed | K9: =IF(A9="","",DATE(YEAR(A9),MONTH(A9),1)) | L9: =IF(F9<>"",LOWER(TRIM(F9)),D9) | M9: =IF(L9="","",IF(COUNTIF($L$2:L9,L9)=1,1,0))
A10: 45948.417 | B10: Dubai Retail Sales | C10: Omar | D10: wamid-0009 | E10: Sale: customer=Meera Shah, product=AirPods Pro, amount=17199, phone=9149203558 | F10: Meera Shah | G10: AirPods Pro | H10: 17199 | I10: 9149203558 | J10: parsed | K10: =IF(A10="","",DATE(YEAR(A10),MONTH(A10),1)) | L10: =IF(F10<>"",LOWER(TRIM(F10)),D10) | M10: =IF(L10="","",IF(COUNTIF($L$2:L10,L10)=1,1,0))
A11: 45950.417 | B11: Dubai Retail Sales | C11: Fatima | D11: wamid-0010 | E11: Sale: customer=Meera Shah, product=Galaxy S24, amount=45999, phone=9508157429 | F11: Meera Shah | G11: Galaxy S24 | H11: 45999 | I11: 9508157429 | J11: parsed | K11: =IF(A11="","",DATE(YEAR(A11),MONTH(A11),1)) | L11: =IF(F11<>"",LOWER(TRIM(F11)),D11) | M11: =IF(L11="","",IF(COUNTIF($L$2:L11,L11)=1,1,0))
A12: 45952.417 | B12: Dubai Retail Sales | C12: Fatima | D12: wamid-0011 | E12: Sale: customer=Sara James, product=Apple Watch, amount=22999, phone=9819595113 | F12: Sara James | G12: Apple Watch | H12: 22999 | I12: 9819595113 | J12: parsed | K12: =IF(A12="","",DATE(YEAR(A12),MONTH(A12),1)) | L12: =IF(F12<>"",LOWER(TRIM(F12)),D12) | M12: =IF(L12="","",IF(COUNTIF($L$2:L12,L12)=1,1,0))
A13: 45955.417 | B13: Dubai Retail Sales | C13: Rahul | D13: wamid-0012 | E13: Sale: customer=Yusuf Ahmed, product=MacBook Air, amount=83199, phone=9882893941 | F13: Yusuf Ahmed | G13: MacBook Air | H13: 83199 | I13: 9882893941 | J13: parsed | K13: =IF(A13="","",DATE(YEAR(A13),MONTH(A13),1)) | L13: =IF(F13<>"",LOWER(TRIM(F13)),D13) | M13: =IF(L13="","",IF(COUNTIF($L$2:L13,L13)=1,1,0))
... A20: 45969.417 | B20: Dubai Retail Sales | C20: Rahul | D20: wamid-0019 | E20: Sale: customer=Ali Khan, product=Apple Watch, amount=22999, phone=9773715057 | F20: Ali Khan | G20: Apple Watch | H20: 22999 | I20: 9773715057 | J20: parsed | K20: =IF(A20="","",DATE(YEAR(A20),MONTH(A20),1)) | L20: =IF(F20<>"",LOWER(TRIM(F20)),D20) | M20: =IF(L20="","",IF(COUNTIF($L$2:L20,L20)=1,1,0))
A21: 45970.417 | B21: Dubai Retail Sales | C21: Priya | D21: wamid-0020 | E21: Sale: customer=unknown, product=MacBook Air, amount=83199, phone=9509760584 | H21: 0 | J21: failed | K21: =IF(A21="","",DATE(YEAR(A21),MONTH(A21),1)) | L21: =IF(F21<>"",LOWER(TRIM(F21)),D21) | M21: =IF(L21="","",IF(COUNTIF($L$2:L21,L21)=1,1,0))
A22: 45972.417 | B22: Dubai Retail Sales | C22: Omar | D22: wamid-0021 | E22: Sale: customer=John Doe, product=Apple Watch, amount=21199, phone=9830448745 | F22: John Doe | G22: Apple Watch | H22: 21199 | I22: 9830448745 | J22: parsed | K22: =IF(A22="","",DATE(YEAR(A22),MONTH(A22),1)) | L22: =IF(F22<>"",LOWER(TRIM(F22)),D22) | M22: =IF(L22="","",IF(COUNTIF($L$2:L22,L22)=1,1,0))
A23: 45974.417 | B23: Dubai Retail Sales | C23: Rahul | D23: wamid-0022 | E23: Sale: customer=Rohan Patel, product=iPhone 15, amount=47499, phone=9566825638 | F23: Rohan Patel | G23: iPhone 15 | H23: 47499 | I23: 9566825638 | J23: parsed | K23: =IF(A23="","",DATE(YEAR(A23),MONTH(A23),1)) | L23: =IF(F23<>"",LOWER(TRIM(F23)),D23) | M23: =IF(L23="","",IF(COUNTIF($L$2:L23,L23)=1,1,0))
A24: 45977.417 | B24: Dubai Retail Sales | C24: Rahul | D24: wamid-0023 | E24: Sale: customer=Rohan Patel, product=Apple Watch, amount=20499, phone=9637500247 | F24: Rohan Patel | G24: Apple Watch | H24: 20499 | I24: 9637500247 | J24: parsed | K24: =IF(A24="","",DATE(YEAR(A24),MONTH(A24),1)) | L24: =IF(F24<>"",LOWER(TRIM(F24)),D24) | M24: =IF(L24="","",IF(COUNTIF($L$2:L24,L24)=1,1,0))
A25: 45979.417 | B25: Dubai Retail Sales | C25: Priya | D25: wamid-0024 | E25: Sale: customer=Leah Thomas, product=iPad Air, amount=30499, phone=9645098869 | F25: Leah Thomas | G25: iPad Air | H25: 30499 | I25: 9645098869 | J25: parsed | K25: =IF(A25="","",DATE(YEAR(A25),MONTH(A25),1)) | L25: =IF(F25<>"",LOWER(TRIM(F25)),D25) | M25: =IF(L25="","",IF(COUNTIF($L$2:L25,L25)=1,1,0))
A26: 45981.417 | B26: Dubai Retail Sales | C26: Priya | D26: wamid-0025 | E26: Sale: customer=Yusuf Ahmed, product=Galaxy S24, amount=45999, phone=9936043811 | F26: Yusuf Ahmed | G26: Galaxy S24 | H26: 45999 | I26: 9936043811 | J26: parsed | K26: =IF(A26="","",DATE(YEAR(A26),MONTH(A26),1)) | L26: =IF(F26<>"",LOWER(TRIM(F26)),D26) | M26: =IF(L26="","",IF(COUNTIF($L$2:L26,L26)=1,1,0))
A27: 45982.417 | B27: Dubai Retail Sales | C27: Fatima | D27: wamid-0026 | E27: Sale: customer=unknown, product=iPhone 15, amount=48799, phone=9489747629 | H27: 0 | J27: failed | K27: =IF(A27="","",DATE(YEAR(A27),MONTH(A27),1)) | L27: =IF(F27<>"",LOWER(TRIM(F27)),D27) | M27: =IF(L27="","",IF(COUNTIF($L$2:L27,L27)=1,1,0))
A28: 45985.417 | B28: Dubai Retail Sales | C28: Omar | D28: wamid-0027 | E28: Sale: customer=Meera Shah, product=Galaxy S24, amount=45999, phone=9191969690 | F28: Meera Shah | G28: Galaxy S24 | H28: 45999 | I28: 9191969690 | J28: parsed | K28: =IF(A28="","",DATE(YEAR(A28),MONTH(A28),1)) | L28: =IF(F28<>"",LOWER(TRIM(F28)),D28) | M28: =IF(L28="","",IF(COUNTIF($L$2:L28,L28)=1,1,0))
A29: 45987.417 | B29: Dubai Retail Sales | C29: Noah | D29: wamid-0028 | E29: Sale: customer=Ali Khan, product=Apple Watch, amount=21199, phone=9808402051 | F29: Ali Khan | G29: Apple Watch | H29: 21199 | I29: 9808402051 | J29: parsed | K29: =IF(A29="","",DATE(YEAR(A29),MONTH(A29),1)) | L29: =IF(F29<>"",LOWER(TRIM(F29)),D29) | M29: =IF(L29="","",IF(COUNTIF($L$2:L29,L29)=1,1,0))
A30: 45989.417 | B30: Dubai Retail Sales | C30: Rahul | D30: wamid-0029 | E30: Sale: customer=Anya Verma, product=iPad Air, amount=32999, phone=9554340903 | F30: Anya Verma | G30: iPad Air | H30: 32999 | I30: 9554340903 | J30: parsed | K30: =IF(A30="","",DATE(YEAR(A30),MONTH(A30),1)) | L30: =IF(F30<>"",LOWER(TRIM(F30)),D30) | M30: =IF(L30="","",IF(COUNTIF($L$2:L30,L30)=1,1,0))
A31: 45991.417 | B31: Dubai Retail Sales | C31: Fatima | D31: wamid-0030 | E31: Sale: customer=Leah Thomas, product=iPad Air, amount=30499, phone=9797801251 | F31: Leah Thomas | G31: iPad Air | H31: 30499 | I31: 9797801251 | J31: parsed | K31: =IF(A31="","",DATE(YEAR(A31),MONTH(A31),1)) | L31: =IF(F31<>"",LOWER(TRIM(F31)),D31) | M31: =IF(L31="","",IF(COUNTIF($L$2:L31,L31)=1,1,0))
A32: 45992.417 | B32: Dubai Retail Sales | C32: Aisha | D32: wamid-0031 | E32: Sale: customer=Meera Shah, product=Apple Watch, amount=22999, phone=9463016614 | F32: Meera Shah | G32: Apple Watch | H32: 22999 | I32: 9463016614 | J32: parsed | K32: =IF(A32="","",DATE(YEAR(A32),MONTH(A32),1)) | L32: =IF(F32<>"",LOWER(TRIM(F32)),D32) | M32: =IF(L32="","",IF(COUNTIF($L$2:L32,L32)=1,1,0))
A33: 45995.417 | B33: Dubai Retail Sales | C33: Omar | D33: wamid-0032 | E33: Sale: customer=Meera Shah, product=iPad Air, amount=31199, phone=9860038427 | F33: Meera Shah | G33: iPad Air | H33: 31199 | I33: 9860038427 | J33: parsed | K33: =IF(A33="","",DATE(YEAR(A33),MONTH(A33),1)) | L33: =IF(F33<>"",LOWER(TRIM(F33)),D33) | M33: =IF(L33="","",IF(COUNTIF($L$2:L33,L33)=1,1,0))
A34: 45997.417 | B34: Dubai Retail Sales | C34: Priya | D34: wamid-0033 | E34: Sale: customer=Nora Salem, product=iPhone 15, amount=49999, phone=9176082500 | F34: Nora Salem | G34: iPhone 15 | H34: 49999 | I34: 9176082500 | J34: parsed | K34: =IF(A34="","",DATE(YEAR(A34),MONTH(A34),1)) | L34: =IF(F34<>"",LOWER(TRIM(F34)),D34) | M34: =IF(L34="","",IF(COUNTIF($L$2:L34,L34)=1,1,0))
A35: 45998.417 | B35: Dubai Retail Sales | C35: Omar | D35: wamid-0034 | E35: Sale: customer=Yusuf Ahmed, product=Galaxy S24, amount=43499, phone=9242068763 | F35: Yusuf Ahmed | G35: Galaxy S24 | H35: 43499 | I35: 9242068763 | J35: parsed | K35: =IF(A35="","",DATE(YEAR(A35),MONTH(A35),1)) | L35: =IF(F35<>"",LOWER(TRIM(F35)),D35) | M35: =IF(L35="","",IF(COUNTIF($L$2:L35,L35)=1,1,0))
A36: 46000.417 | B36: Dubai Retail Sales | C36: Aisha | D36: wamid-0035 | E36: Sale: customer=Kabir Singh, product=iPad Air, amount=32999, phone=9304451095 | F36: Kabir Singh | G36: iPad Air | H36: 32999 | I36: 9304451095 | J36: parsed | K36: =IF(A36="","",DATE(YEAR(A36),MONTH(A36),1)) | L36: =IF(F36<>"",LOWER(TRIM(F36)),D36) | M36: =IF(L36="","",IF(COUNTIF($L$2:L36,L36)=1,1,0))
A37: 46002.417 | B37: Dubai Retail Sales | C37: Aisha | D37: wamid-0036 | E37: Sale: customer=Emma Clark, product=iPhone 15, amount=49999, phone=9882839238 | F37: Emma Clark | G37: iPhone 15 | H37: 49999 | I37: 9882839238 | J37: parsed | K37: =IF(A37="","",DATE(YEAR(A37),MONTH(A37),1)) | L37: =IF(F37<>"",LOWER(TRIM(F37)),D37) | M37: =IF(L37="","",IF(COUNTIF($L$2:L37,L37)=1,1,0))
A38: 46005.417 | B38: Dubai Retail Sales | C38: Aisha | D38: wamid-0037 | E38: Sale: customer=Nora Salem, product=MacBook Air, amount=84999, phone=9959629660 | F38: Nora Salem | G38: MacBook Air | H38: 84999 | I38: 9959629660 | J38: parsed | K38: =IF(A38="","",DATE(YEAR(A38),MONTH(A38),1)) | L38: =IF(F38<>"",LOWER(TRIM(F38)),D38) | M38: =IF(L38="","",IF(COUNTIF($L$2:L38,L38)=1,1,0))
A39: 46007.417 | B39: Dubai Retail Sales | C39: Rahul | D39: wamid-0038 | E39: Sale: customer=Ali Khan, product=Galaxy S24, amount=45999, phone=9552991960 | F39: Ali Khan | G39: Galaxy S24 | H39: 45999 | I39: 9552991960 | J39: parsed | K39: =IF(A39="","",DATE(YEAR(A39),MONTH(A39),1)) | L39: =IF(F39<>"",LOWER(TRIM(F39)),D39) | M39: =IF(L39="","",IF(COUNTIF($L$2:L39,L39)=1,1,0))
... A57: 46042.417 | B57: Dubai Retail Sales | C57: Omar | D57: wamid-0056 | E57: Sale: customer=John Doe, product=MacBook Air, amount=83199, phone=9199104722 | F57: John Doe | G57: MacBook Air | H57: 83199 | I57: 9199104722 | J57: parsed | K57: =IF(A57="","",DATE(YEAR(A57),MONTH(A57),1)) | L57: =IF(F57<>"",LOWER(TRIM(F57)),D57) | M57: =IF(L57="","",IF(COUNTIF($L$2:L57,L57)=1,1,0))
A58: 46044.417 | B58: Dubai Retail Sales | C58: Rahul | D58: wamid-0057 | E58: Sale: customer=unknown, product=Apple Watch, amount=22999, phone=9927982963 | H58: 0 | J58: failed | K58: =IF(A58="","",DATE(YEAR(A58),MONTH(A58),1)) | L58: =IF(F58<>"",LOWER(TRIM(F58)),D58) | M58: =IF(L58="","",IF(COUNTIF($L$2:L58,L58)=1,1,0))
A59: 46046.417 | B59: Dubai Retail Sales | C59: Noah | D59: wamid-0058 | E59: Sale: customer=Yusuf Ahmed, product=MacBook Air, amount=84999, phone=9857704655 | F59: Yusuf Ahmed | G59: MacBook Air | H59: 84999 | I59: 9857704655 | J59: parsed | K59: =IF(A59="","",DATE(YEAR(A59),MONTH(A59),1)) | L59: =IF(F59<>"",LOWER(TRIM(F59)),D59) | M59: =IF(L59="","",IF(COUNTIF($L$2:L59,L59)=1,1,0))
A60: 46049.417 | B60: Dubai Retail Sales | C60: Rahul | D60: wamid-0059 | E60: Sale: customer=unknown, product=iPad Air, amount=32999, phone=9841976666 | H60: 0 | J60: failed | K60: =IF(A60="","",DATE(YEAR(A60),MONTH(A60),1)) | L60: =IF(F60<>"",LOWER(TRIM(F60)),D60) | M60: =IF(L60="","",IF(COUNTIF($L$2:L60,L60)=1,1,0))
A61: 46051.417 | B61: Dubai Retail Sales | C61: Rahul | D61: wamid-0060 | E61: Sale: customer=Ali Khan, product=iPad Air, amount=32999, phone=9561479973 | F61: Ali Khan | G61: iPad Air | H61: 32999 | I61: 9561479973 | J61: parsed | K61: =IF(A61="","",DATE(YEAR(A61),MONTH(A61),1)) | L61: =IF(F61<>"",LOWER(TRIM(F61)),D61) | M61: =IF(L61="","",IF(COUNTIF($L$2:L61,L61)=1,1,0))
A62: 46052.417 | B62: Dubai Retail Sales | C62: Rahul | D62: wamid-0061 | E62: Sale: customer=John Doe, product=iPhone 15, amount=49999, phone=9484194737 | F62: John Doe | G62: iPhone 15 | H62: 49999 | I62: 9484194737 | J62: parsed | K62: =IF(A62="","",DATE(YEAR(A62),MONTH(A62),1)) | L62: =IF(F62<>"",LOWER(TRIM(F62)),D62) | M62: =IF(L62="","",IF(COUNTIF($L$2:L62,L62)=1,1,0))
A63: 46055.417 | B63: Dubai Retail Sales | C63: Priya | D63: wamid-0062 | E63: Sale: customer=Yusuf Ahmed, product=MacBook Air, amount=82499, phone=9536344399 | F63: Yusuf Ahmed | G63: MacBook Air | H63: 82499 | I63: 9536344399 | J63: parsed | K63: =IF(A63="","",DATE(YEAR(A63),MONTH(A63),1)) | L63: =IF(F63<>"",LOWER(TRIM(F63)),D63) | M63: =IF(L63="","",IF(COUNTIF($L$2:L63,L63)=1,1,0))
...

Sheet Summary
A1: Sales Summary Logic
A3: Metric | B3: Value | F3: Product | G3: Revenue | H3: Orders | J3: Status | K3: Count
A4: Total Revenue | B4: =SUMIFS(RawData!$H$2:$H$5000,RawData!$J$2:$J$5000,"parsed") | F4: MacBook Air | G4: =SUMIFS(RawData!$H$2:$H$5000,RawData!$J$2:$J$5000,"parsed",RawData!$G$2:$G$5000,F4) | H4: =COUNTIFS(RawData!$J$2:$J$5000,"parsed",RawData!$G$2:$G$5000,F4) | J4: parsed | K4: =COUNTIF(RawData!$J$2:$J$5000,"parsed")
A5: Parsed Orders | B5: =COUNTIF(RawData!$J$2:$J$5000,"parsed") | F5: iPhone 15 | G5: =SUMIFS(RawData!$H$2:$H$5000,RawData!$J$2:$J$5000,"parsed",RawData!$G$2:$G$5000,F5) | H5: =COUNTIFS(RawData!$J$2:$J$5000,"parsed",RawData!$G$2:$G$5000,F5) | J5: failed | K5: =COUNTIF(RawData!$J$2:$J$5000,"failed")
A6: Average Order Value | B6: =IFERROR(B4/B5,0) | F6: Galaxy S24 | G6: =SUMIFS(RawData!$H$2:$H$5000,RawData!$J$2:$J$5000,"parsed",RawData!$G$2:$G$5000,F6) | H6: =COUNTIFS(RawData!$J$2:$J$5000,"parsed",RawData!$G$2:$G$5000,F6)
A7: Unique Customers | B7: =SUM(RawData!$M$2:$M$5000) | F7: iPad Air | G7: =SUMIFS(RawData!$H$2:$H$5000,RawData!$J$2:$J$5000,"parsed",RawData!$G$2:$G$5000,F7) | H7: =COUNTIFS(RawData!$J$2:$J$5000,"parsed",RawData!$G$2:$G$5000,F7)
A8: Failed Parses | B8: =COUNTIF(RawData!$J$2:$J$5000,"failed") | F8: Apple Watch | G8: =SUMIFS(RawData!$H$2:$H$5000,RawData!$J$2:$J$5000,"parsed",RawData!$G$2:$G$5000,F8) | H8: =COUNTIFS(RawData!$J$2:$J$5000,"parsed",RawData!$G$2:$G$5000,F8)
A9: Top Product | B9: =INDEX(F4:F9,MATCH(MAX(G4:G9),G4:G9,0)) | F9: AirPods Pro | G9: =SUMIFS(RawData!$H$2:$H$5000,RawData!$J$2:$J$5000,"parsed",RawData!$G$2:$G$5000,F9) | H9: =COUNTIFS(RawData!$J$2:$J$5000,"parsed",RawData!$G$2:$G$5000,F9)
A12: Month | B12: Revenue | C12: Orders
A13: =DATE(YEAR(TODAY()),MONTH(TODAY())-5,1) | B13: =SUMIFS(RawData!$H$2:$H$5000,RawData!$J$2:$J$5000,"parsed",RawData!$K$2:$K$5000,$A13) | C13: =COUNTIFS(RawData!$J$2:$J$5000,"parsed",RawData!$K$2:$K$5000,$A13)
A14: =DATE(YEAR(A13),MONTH(A13)+1,1) | B14: =SUMIFS(RawData!$H$2:$H$5000,RawData!$J$2:$J$5000,"parsed",RawData!$K$2:$K$5000,$A14) | C14: =COUNTIFS(RawData!$J$2:$J$5000,"parsed",RawData!$K$2:$K$5000,$A14)
A15: =DATE(YEAR(A14),MONTH(A14)+1,1) | B15: =SUMIFS(RawData!$H$2:$H$5000,RawData!$J$2:$J$5000,"parsed",RawData!$K$2:$K$5000,$A15) | C15: =COUNTIFS(RawData!$J$2:$J$5000,"parsed",RawData!$K$2:$K$5000,$A15)
A16: =DATE(YEAR(A15),MONTH(A15)+1,1) | B16: =SUMIFS(RawData!$H$2:$H$5000,RawData!$J$2:$J$5000,"parsed",RawData!$K$2:$K$5000,$A16) | C16: =COUNTIFS(RawData!$J$2:$J$5000,"parsed",RawData!$K$2:$K$5000,$A16)
A17: =DATE(YEAR(A16),MONTH(A16)+1,1) | B17: =SUMIFS(RawData!$H$2:$H$5000,RawData!$J$2:$J$5000,"parsed",RawData!$K$2:$K$5000,$A17) | C17: =COUNTIFS(RawData!$J$2:$J$5000,"parsed",RawData!$K$2:$K$5000,$A17)
A18: =DATE(YEAR(A17),MONTH(A17)+1,1) | B18: =SUMIFS(RawData!$H$2:$H$5000,RawData!$J$2:$J$5000,"parsed",RawData!$K$2:$K$5000,$A18) | C18: =COUNTIFS(RawData!$J$2:$J$5000,"parsed",RawData!$K$2:$K$5000,$A18)

Sheet Dashboard
A1: WhatsApp Sales Dashboard
A2: Built for the WhatsApp-to-Google-Sheets sales flow in this repo. Replace sample rows on RawData to refresh the view.
A4: Total Revenue | D4: Parsed Orders | G4: Average Order Value | J4: Unique Customers
A5: =Summary!B4 | D5: =Summary!B5 | G5: =Summary!B6 | J5: =Summary!B7
A8: Failed Parses | D8: Top Product | G8: Sources: https://web.whatsapp.com/ https://developers.google.com/sheets/api Schema aligned to the local project README.
A9: =Summary!B8 | D9: =Summary!B9

Sheet Instructions
A1: How To Use This Dashboard
A3: 1. Replace the example rows on RawData with exports from your Google Sheet.
A4: 2. Keep the column order from A:J unchanged so the formulas continue to work.
A5: 3. Columns K:M are helper formulas; leave them in place and copy them downward for new rows if Excel does not autofill them.
A6: 4. If you introduce new product names, update Summary!F4:F9 so the product chart reflects your catalog.
A7: 5. Open the workbook in Excel or Google Sheets to refresh formulas and chart values.
